Workbook

Sheet Read me
A1: Marketplace import arbitrage calculator
A2: China factory (FOB) → Australia → sold new on Facebook Marketplace (local pickup). Data as at 9 October 2026.
A4: What it does
A5: Calculates landed cost per unit, gross profit (GP), GP % and the cash needed for the 19 products verified in our research (18 shortlisted SKUs plus the recovery-kit + tracks bundle variant) – including the ones that failed verification, with their verdict and revised score so you can see why. Each row is pre-filled with the verify note's recommended first order (shipping mode, quantity and price), so the numbers reconcile with the notes until you overwrite them.
A6: How to use it
A7: 1. Blue cells are inputs – overwrite them. Black cells are formulas, green cells link from another sheet, grey italic cells are reference figures copied from the notes (not inputs).
A8: 2. Assumptions – global inputs: FX, freight per CBM for LCL / 20GP / 40HQ, container weight caps, duty with the ChAFTA Certificate-of-Origin toggle, GST, inspection, defect allowance, storage, Marketplace fee and the pricing rule.
A9: 3. Products – as supplier quotes arrive, overwrite FOB (and its unit: per piece / pair / kg), MOQ, carton CBM / kg and compliance costs; pick the shipping mode from the dropdown and set the order quantity. Flags warn about MOQ, extra boxes, a cheaper freight mode, prices that break the 10–20%-below rule, missing data and losses.
A10: 4. Mixed container – combine SKUs in one 20GP or 40HQ (pre-filled with the gym and outdoor mixes from the notes) and check CBM and weight utilisation, cash, GP and GP %.
A11: 5. Sensitivity – GP per unit for the top-scored SKUs under FX, freight, duty, sale-price and FOB shocks. 6. Sources – the URLs behind every price, supplier and compliance figure, copied from the notes.
A12: Read before relying on it
A13: • Factory prices are PUBLIC LISTING PRICES (mostly Made-in-China.com tiers), NOT QUOTES – no RFQ was sent, Incoterms are mostly unstated and several cartons / weights are estimates (see the notes columns on Products). Replace them with real quotes before committing cash.
... A16: • Assumes a GST-registered seller: net revenue = price ÷ 1.1 and import GST is a reclaimable cash float. Product-liability insurance, returns / warranty and your time are not costed except where a note includes them (e.g. the recovery kit).
B18: Colour key | C18: Input (overwrite) | D18: Formula | F18: Link from another sheet | I18: Reference figure from the notes | K18: Loss / overfill / BROKEN
A20: Reconciliation – workbook GP per unit vs the verify notes (pre-filled base case)
A21: Same scenario as the note (mode, quantity, price, FOB, carton, compliance). Differences come only from small convention differences between the five notes; every SKU agrees within A$0.50 per unit. The comparison updates live, so it will drift once you overwrite inputs.
A22: # | B22: SKU | C22: Pre-filled scenario (from the note) | D22: Notes GP (A$/unit) | E22: Workbook GP (A$/unit) | F22: Difference (A$) | G22: Notes GP % | H22: Workbook GP % | I22: Within A$3? | J22: Reason for any difference | K22: Source note
A23: 1 | B23: Trampoline 14ft + enclosure | C23: 20GP, 128 units, A$349 | D23: 97.07 | E23: =Products!BE5 -> 97.064391 | F23: =IF(ISNUMBER(D23),E23-D23,"") -> -0.0056090269 | G23: 0.306 | H23: =Products!BF5 -> 0.30593361 | I23: =IF(ISNUMBER(F23),IF(ABS(F23)<=3,"Yes","No"),"") -> Yes | J23: Same method as the note; only FX rounding (A$1.4376 vs 1 ÷ 0.6956). | K23: verify_kids.md Q1
A24: 2 | B24: Kids 24V 2-seat UTV | C24: 20GP, 98 units, A$299 | D24: -19.57 | E24: =Products!BE6 -> -19.567238 | F24: =IF(ISNUMBER(D24),E24-D24,"") -> 0.0027623389 | G24: -0.072 | H24: =Products!BF6 -> -0.071986493 | I24: =IF(ISNUMBER(F24),IF(ABS(F24)<=3,"Yes","No"),"") -> Yes | J24: Same method as the note. | K24: verify_kids.md Q2
A25: 3 | B25: Timber cubby house | C25: 40HQ (part-filled), 300 units, A$299 | D25: 67.89 | E25: =Products!BE7 -> 67.887172 | F25: =IF(ISNUMBER(D25),E25-D25,"") -> -0.0028283601 | G25: 0.25 | H25: =Products!BF7 -> 0.24975214 | I25: =IF(ISNUMBER(F25),IF(ABS(F25)<=3,"Yes","No"),"") -> Yes | J25: Same method as the note (part-filled 40HQ costs the whole box). | K25: verify_kids.md Q3
A26: 4 | B26: 3-in-1 high chair | C26: LCL, 150 units, A$79 | D26: -28.67 | E26: =Products!BE8 -> -28.660289 | F26: =IF(ISNUMBER(D26),E26-D26,"") -> 0.0097111523 | G26: -0.399 | H26: =Products!BF8 -> -0.39906731 | I26: =IF(ISNUMBER(F26),IF(ABS(F26)<=3,"Yes","No"),"") -> Yes | J26: Same method as the note (flat A$5 handling). | K26: verify_kids.md Q4
A27: 5 | B27: Dual-motor standing desk | C27: LCL, 100 units, A$299 | D27: 46.96 | E27: =Products!BE9 -> 47.059159 | F27: =IF(ISNUMBER(D27),E27-D27,"") -> 0.099159298 | G27: 0.173 | H27: =Products!BF9 -> 0.17312734 | I27: =IF(ISNUMBER(F27),IF(ABS(F27)<=3,"Yes","No"),"") -> Yes | J27: verify_furniture.md applies the 3% defect allowance to storage too; the workbook applies it before storage (as the kids, outdoor and camping notes do). | K27: verify_furniture.md Q1
A28: 6 | B28: Manual fabric recliner | C28: 20GP, 84 units, A$139 | D28: -95.83 | E28: =Products!BE10 -> -95.502166 | F28: =IF(ISNUMBER(D28),E28-D28,"") -> 0.32783358 | G28: n/s | H28: =Products!BF10 -> -0.75577254 | I28: =IF(ISNUMBER(F28),IF(ABS(F28)<=3,"Yes","No"),"") -> Yes | J28: As SKU 5 (defect allowance on storage in the note). | K28: verify_furniture.md Q2
A29: 7 | B29: Fluted/LED TV unit 160cm | C29: LCL, 100 units, A$129 | D29: -15.33 | E29: =Products!BE11 -> -15.183395 | F29: =IF(ISNUMBER(D29),E29-D29,"") -> 0.14660479 | G29: n/s | H29: =Products!BF11 -> -0.12947081 | I29: =IF(ISNUMBER(F29),IF(ABS(F29)<=3,"Yes","No"),"") -> Yes | J29: As SKU 5 (defect allowance on storage in the note). | K29: verify_furniture.md Q3
A30: 8 | B30: Queen pocket-spring mattress | C30: LCL, 100 units, A$165 | D30: 2.7 | E30: =Products!BE12 -> 2.8454927 | F30: =IF(ISNUMBER(D30),E30-D30,"") -> 0.14549274 | G30: 0.018 | H30: =Products!BF12 -> 0.018969952 | I30: =IF(ISNUMBER(F30),IF(ABS(F30)<=3,"Yes","No"),"") -> Yes | J30: As SKU 5 (defect allowance on storage in the note). | K30: verify_furniture.md Q4
A31: 9 | B31: 100kg bumper plate set | C31: 20GP (weight-capped), 211 sets, A$339 | D31: 79.47 | E31: =Products!BE13 -> 79.893524 | F31: =IF(ISNUMBER(D31),E31-D31,"") -> 0.42352437 | G31: 0.258 | H31: =Products!BF13 -> 0.25924152 | I31: =IF(ISNUMBER(F31),IF(ABS(F31)<=3,"Yes","No"),"") -> Yes | J31: verify_gym_pets.md used A$5,964 per 20GP (vs A$211 × 28 = A$5,908 in the brief) and applied the 3% allowance to the A$5 handling. | K31: verify_gym_pets.md Q1
A32: 10 | B32: 2x40kg dial dumbbell pair | C32: 20GP (volume-limited), 215 pairs, A$379 | D32: 57.18 | E32: =Products!BE14 -> 57.600604 | F32: =IF(ISNUMBER(D32),E32-D32,"") -> 0.42060423 | G32: 0.166 | H32: =Products!BF14 -> 0.16717853 | I32: =IF(ISNUMBER(F32),IF(ABS(F32)<=3,"Yes","No"),"") -> Yes | J32: As SKU 9 (A$5,964 box and allowance on handling in the note). | K32: verify_gym_pets.md Q2
A33: 11 | B33: Kettlebell set 8/12/16kg | C33: 20GP (weight-capped), 581 sets, A$99 | D33: 9.6 | E33: =Products!BE15 -> 9.8493453 | F33: =IF(ISNUMBER(D33),E33-D33,"") -> 0.24934527 | G33: 0.107 | H33: =Products!BF15 -> 0.10943717 | I33: =IF(ISNUMBER(F33),IF(ABS(F33)<=3,"Yes","No"),"") -> Yes | J33: As SKU 9 (A$5,964 box and allowance on handling in the note). | K33: verify_gym_pets.md Q3
A34: 12 | B34: 48in steel dog crate | C34: 20GP (volume-limited), 288 crates, A$85 | D34: 7.16 | E34: =Products!BE16 -> 7.5118886 | F34: =IF(ISNUMBER(D34),E34-D34,"") -> 0.35188859 | G34: 0.093 | H34: =Products!BF16 -> 0.097212676 | I34: =IF(ISNUMBER(F34),IF(ABS(F34)<=3,"Yes","No"),"") -> Yes | J34: As SKU 9 (A$5,964 box and allowance on handling in the note). | K34: verify_gym_pets.md Q4
A35: 13 | B35: Wood/pellet pizza oven | C35: LCL, 200 units, A$125 | D35: 13.77 | E35: =Products!BE17 -> 13.771121 | F35: =IF(ISNUMBER(D35),E35-D35,"") -> 0.0011208598 | G35: 0.12 | H35: =Products!BF17 -> 0.12118586 | I35: =IF(ISNUMBER(F35),IF(ABS(F35)<=3,"Yes","No"),"") -> Yes | J35: Same method as the note (exact carton 0.077826 CBM). | K35: verify_outdoor.md Q1
A36: 14 | B36: Double hammock + steel stand | C36: LCL, 200 units, A$95 | D36: 28.58 | E36: =Products!BE18 -> 28.584148 | F36: =IF(ISNUMBER(D36),E36-D36,"") -> 0.0041478443 | G36: 0.33 | H36: =Products!BF18 -> 0.33097434 | I36: =IF(ISNUMBER(F36),IF(ABS(F36)<=3,"Yes","No"),"") -> Yes | J36: Same method as the note (exact carton 0.061248 CBM). | K36: verify_outdoor.md Q2
A37: 15 | B37: Foldable hanging egg chair | C37: 20GP, 196 units, A$159 | D37: 30.03 | E37: =Products!BE19 -> 30.026117 | F37: =IF(ISNUMBER(D37),E37-D37,"") -> -0.0038829086 | G37: 0.21 | H37: =Products!BF19 -> 0.20772785 | I37: =IF(ISNUMBER(F37),IF(ABS(F37)<=3,"Yes","No"),"") -> Yes | J37: Same method; carton entered as 0.1426 CBM (115×62×20 cm) so 196 chairs fit one 20GP as in the note (the note rounds to 0.143). | K37: verify_outdoor.md Q3
A38: 16 | B38: 4WD recovery kit | C38: LCL, 200 kits, A$119 | D38: 16.3 | E38: =Products!BE20 -> 16.29732 | F38: =IF(ISNUMBER(D38),E38-D38,"") -> -0.0026798055 | G38: 0.151 | H38: =Products!BF20 -> 0.1506475 | I38: =IF(ISNUMBER(F38),IF(ABS(F38)<=3,"Yes","No"),"") -> Yes | J38: Same method as the note (A$4,000 fixed compliance, US$1 labels, A$5 handling). | K38: verify_camping_appliance.md Q2–Q3
A39: 17 | B39: Alu camp kitchen + cupboards | C39: 20GP, 500 units, A$99 | D39: 28.32 | E39: =Products!BE21 -> 28.323806 | F39: =IF(ISNUMBER(D39),E39-D39,"") -> 0.0038063715 | G39: 0.315 | H39: =Products!BF21 -> 0.31470896 | I39: =IF(ISNUMBER(F39),IF(ABS(F39)<=3,"Yes","No"),"") -> Yes | J39: Same method as the note. | K39: verify_camping_appliance.md Q4
A40: 18 | B40: 2000W pressure washer | C40: LCL, 500 units, A$99 (Scenario A) | D40: 22.4 | E40: =Products!BE22 -> 22.401779 | F40: =IF(ISNUMBER(D40),E40-D40,"") -> 0.0017785934 | G40: 0.249 | H40: =Products!BF22 -> 0.24890865 | I40: =IF(ISNUMBER(F40),IF(ABS(F40)<=3,"Yes","No"),"") -> Yes | J40: Same method as the note (5% defect allowance for electricals). | K40: verify_camping_appliance.md Q5–Q6
A41: 19 | B41: Recovery kit + tracks bundle | C41: LCL, 100 bundles, A$179 | D41: =G41*Products!BD23 -> -1.6272727 | E41: =Products!BE23 -> -1.5547655 | F41: =IF(ISNUMBER(D41),E41-D41,"") -> 0.07250718 | G41: -0.01 | H41: =Products!BF23 -> -0.0095544252 | I41: =IF(ISNUMBER(F41),IF(ABS(F41)<=3,"Yes","No"),"") -> Yes | J41: Note gives GP % only (−1.0% at A$179, 100 bundles); the A$ comparison uses that % × net revenue. | K41: verify_camping_appliance.md Q2 & Q7
A42: Mix 1 | B42: Gym 20GP: 150 bumper + 70 dial pairs | C42: Total GP for the container (A$) – see Mixed container | D42: 15751 | E42: ='Mixed container'!N9 -> 15841.102 | F42: =E42-D42 -> 90.102412 | G42: 0.224 | H42: ='Mixed container'!O9 -> 0.22519014 | I42: =IF(ABS(F42)<=0.01*ABS(D42),"Yes (<1%)","No") -> Yes (<1%) | J42: verify_gym_pets.md priced the 20GP at A$5,964 (vs A$5,908) and applied the allowance to the A$5 handling (~A$0.40/unit × 220 units). | K42: verify_gym_pets.md Q5 (M4)
A43: Mix 2 | B43: Outdoor 40HQ: 250 ovens + 300 hammocks + 200 egg chairs | C43: Total GP for the container (A$) – see Mixed container | D43: 25119 | E43: ='Mixed container'!N28 -> 25118.587 | F43: =E43-D43 -> -0.4132867 | H43: ='Mixed container'!O28 -> 0.30180716 | I43: =IF(ABS(F43)<=0.01*ABS(D43),"Yes (<1%)","No") -> Yes (<1%) | J43: Same method: every line is volume-bound, so the chargeable-share allocation equals the note's A$151.68 per loaded CBM; consolidation A$800 per leg (estimate) included. | K43: verify_outdoor.md Q4
A45: Cash: as specified, the workbook shows cash = landed cost × quantity (which includes the defect allowance and 3 months' storage / handling) plus the import-GST float. The notes define cash differently – kids and furniture use landed × qty; gym uses the pre-allowance subtotal × qty; outdoor and camping use FOB + freight + inspection + compliance – so cash figures will not match the notes exactly even where GP does.
A46: GST float: the workbook uses GST × (FOB + duty + 60% of door-delivered freight), following verify_gym_pets.md; verify_outdoor.md used 10% × (FOB + freight). Recovery-kit total landed cost is not stated in its note, and the kit + tracks bundle's note gives GP % only. Notes GP % 'n/s' = not stated in the note.
...

Sheet Assumptions
A1: Assumptions – global inputs
A2: Blue cells are inputs. Base values are the shared base used by all five verify_*.md notes (data as at 9 Oct 2026), so results reconcile with the notes. Every formula in the workbook refers to these cells by name.
A4: Group | B4: Input | C4: Value | D4: Unit | E4: Source / note
A5: FX | B5: AUD/USD exchange rate (US$ per A$1) | C5: 0.6956 | D5: US$ per A$ | E5: RBA F11.1, 8 Oct 2026 (US$1 = A$1.4376) – the FX used in every verify note. Lower AUD/USD = dearer imports.
A6: FX | B6: US$1 in A$ (calculated) | C6: =1/FX_AUDUSD -> 1.4376078 | D6: A$ per US$ | E6: Converts FOB and US$ per-unit costs to A$.
A7: Freight | B7: 40HQ door-delivered rate | C7: 148 | D7: A$ per CBM | E7: Coordinator's shared base (all five verify notes), door-delivered and assumed to cover ocean, destination charges, broker, IPC/DAFF and delivery (verify_furniture.md). Not a forwarder quote.
A8: Freight | B8: 40HQ usable volume | C8: 68 | D8: CBM | E8: Shared base.
A9: Freight | B9: 40HQ cost per box (calculated) | C9: =RATE_40HQ*CBM_40HQ -> 10064 | D9: A$ per box | E9: A$10,064 at base. A part-filled box still costs the whole box (verify_kids.md).
A10: Freight | B10: 40HQ cargo weight cap | C10: 22000 | D10: kg | E10: Road limits vary by state (ICE Cargo guide): 40ft HC 22.5 t NSW / 22.0 t VIC / 20.0 t QLD-SA-WA-TAS. 22.0 t matches verify_furniture.md (571-desk, weight-limited 40HQ). Set your own state's limit.
A11: Freight | B11: 20GP door-delivered rate | C11: 211 | D11: A$ per CBM | E11: Shared base. Note: verify_gym_pets.md priced the 20GP at A$5,964 (≈A$213/CBM); the other notes use A$211 × 28 = A$5,908.
A12: Freight | B12: 20GP usable volume | C12: 28 | D12: CBM | E12: Shared base.
A13: Freight | B13: 20GP cost per box (calculated) | C13: =RATE_20GP*CBM_20GP -> 5908 | D13: A$ per box | E13: A$5,908 at base.
A14: Freight | B14: 20GP cargo weight cap | C14: 21800 | D14: kg | E14: 21.8 t = QLD/SA/WA/TAS limit (NSW 24.3 t, VIC 23.8 t) per ICE Cargo, as used in verify_gym_pets.md and verify_kids.md.
A15: Freight | B15: LCL rate | C15: 244 | D15: A$ per W/M | E15: Shared base. W/M = the greater of the shipment's CBM or tonnes.
A16: Freight | B16: LCL fixed charge | C16: 900 | D16: A$ per shipment | E16: Shared base; spread over the order quantity.
A17: Freight | B17: Other fixed costs per order not in the freight rate | C17: 0 | D17: A$ per order | E17: Optional (0 in all notes). The door rates above are all-in; add e.g. ABF IPC A$50 (<A$10k) / A$152 (≥A$10k) + DAFF FID charge A$71 if a forwarder quote excludes them.
A18: Duty | B18: General tariff rate (no Certificate of Origin) | C18: 0.05 | D18: % of FOB | E18: Most shortlisted lines are 5% general; some are Free (set per SKU on Products). Duty is charged on the FOB-based customs value (au_landed_cost_compliance.md §2).
A19: Duty | B19: ChAFTA preferential rate (with CoO) | C19: 0 | D19: % of FOB | E19: ChAFTA: tariffs eliminated since 1 Jan 2019, but only with a valid Certificate of Origin held at import (DFAT; ACN 2026/24).
A20: Duty | B20: ChAFTA Certificate of Origin held? | C20: Yes | D20: Yes / No | E20: Toggle. Yes = ChAFTA rate (0%); No = general rate on dutiable SKUs. Make the CoO a purchase-order term.
A21: Duty | B21: Duty rate applied to dutiable SKUs (calculated) | C21: =IF(COO_HELD="Yes",DUTY_CHAFTA,DUTY_GENERAL) -> 0 | D21: % of FOB | E21: Used by every SKU not marked duty-free at the general rate.
A22: Tax | B22: GST rate | C22: 0.1 | D22: % | E22: Net revenue = price ÷ (1 + GST). Assumes a GST-registered seller, so import GST is a reclaimable float, not a cost.
A23: Tax | B23: Share of door-delivered freight counted as transport & insurance for import GST | C23: 0.6 | D23: % of freight | E23: Import GST = 10% × (customs value + duty + international transport & insurance). Door rates include local charges, so only part counts; 60% is verify_gym_pets.md's estimate.
A24: Costs | B24: Pre-shipment inspection | C24: 400 | D24: A$ per factory per order | E24: Shared base.
A25: Costs | B25: Defect / damage allowance | C25: 0.03 | D25: % of subtotal | E25: Shared base: % of FOB + freight + duty + inspection + compliance + extras (before storage). verify_camping_appliance.md used 5% for the pressure washer (override per SKU on Products).
A26: Costs | B26: Storage rate | C26: 11 | D26: A$ per CBM per month | E26: Shared base.
A27: Costs | B27: Months held | C27: 3 | D27: months | E27: Shared base.
A28: Costs | B28: Storage per CBM over the holding period (calculated) | C28: =STORAGE_RATE*STORAGE_MONTHS -> 33 | D28: A$ per CBM | E28: A$33 per CBM at base; used by SKUs on the 'Per CBM' storage basis.
A29: Costs | B29: Flat handling charge (SKUs set to 'Flat') | C29: 5 | D29: A$ per unit | E29: Used instead of per-CBM storage by verify_gym_pets.md, verify_camping_appliance.md and for the high chair in verify_kids.md.
A30: Selling | B30: Facebook Marketplace selling fee | C30: 0 | D30: % of price | E30: 0% for local pickup. Shipped sales via checkout reportedly 10% (min $1) – not confirmed for Australia (au_landed_cost_compliance.md §8).
A31: Selling | B31: Target discount below price to beat | C31: 0.1 | D31: % | E31: Research pricing rule: sell 10–20% below the cheapest comparable new item. Drives the rule price and the 'discount below target' flag.
A32: Selling | B32: Pricing basis | C32: Manual | D32: Manual / Rule | E32: Manual = use each SKU's 'Target Marketplace price' (pre-filled with the verify notes' prices). Rule = price to beat × (1 − target discount).
A34: Reference only – landed-cost structure from au_landed_cost_compliance.md (not used in formulas: the door-delivered rates above are assumed to include these)
A35: Ocean freight | B35: China → Sydney/Melbourne/Brisbane FCL: 20ft USD 1,500–1,800, 40ft USD 2,900–3,600 (ExFreight, Jun 2026) plus ~USD 1,000/TEU of GRIs announced for Sept 2026 (KLN). LCL USD 60–280 per CBM. LCL and a 20ft cost about the same at ~14–15 CBM.
A36: Destination | B36: Maersk DHC from 1 Oct 2026: Sydney A$600 (20') / A$855 (40'). Terminal landside/infrastructure levies ~A$225–235 per box + vehicle booking ~A$50 + side-loader ~A$90–100. 20ft Sydney landside budget ≈ A$2,150–3,000 per box excluding ocean freight.
A37: Government | B37: ABF Import Processing Charge (electronic): A$50 for consignments A$1,000–<A$10,000; A$152 at A$10,000+. DAFF biosecurity charge on the Full Import Declaration: A$71 (sea) from 1 Jul 2026.
A38: Duty & GST | B38: Duty on the FOB-based customs value: general rate commonly 5% (some lines Free); ChAFTA 0% with a valid CoO. Import GST = 10% × (customs value + duty + transport & insurance); reclaimable for GST-registered importers.
A39: EESS (electrical) | B39: From 1 Jul 2026: Responsible Supplier registration A$239.74/yr; Level 2/3 equipment registration A$89.85 (1 yr). Level 3 items also need an AU/NZ Certificate of Conformity.
A40: Transit | B40: Port-to-port Shanghai/Ningbo → Sydney ~24–25 days (worst case 35–37); Qingdao 28–30 days (KLN, Sept 2026).
A41: Container limits | B41: ICE Cargo guide: 20ft GP 24.3 t NSW / 23.8 t VIC / 21.8 t QLD-SA-WA-TAS; 40ft HC 22.5 / 22.0 / 20.0 t.

Sheet Products
A1: Products – landed cost and Facebook Marketplace GP per verified SKU
A2: Blue cells are inputs: overwrite FOB, MOQ, carton CBM / kg and compliance costs as supplier quotes arrive, and pick the shipping mode and quantity. Black cells are formulas. Each row is pre-filled with the verify note's recommended first order (data as at 9 Oct 2026; FOBs are public listing prices, not quotes). A blank blue cell means the value is missing from the notes (see Flags).
A3: SKU & research verdict | H3: Price (A$ incl. GST) | O3: Supplier – overwrite as quotes arrive | R3: FOB & carton | Y3: Compliance & cost inputs | AG3: Order | AI3: Landed cost build-up (A$ per unit unless stated) | BD3: Results | BR3: Freight-mode check & flags | BW3: Notes from the verify files
A4: # | B4: Category | C4: SKU | D4: SKU spec | E4: Verdict (verify notes, 9 Oct 2026) | F4: Score – original | G4: Score – revised | H4: Price to beat (A$) | I4: Price-to-beat retailer / listing | J4: Price date / basis | K4: Target Marketplace price (A$, incl. GST) | L4: Rule price (A$) = price to beat × (1 − target discount) | M4: Sale price used (A$) | N4: Discount vs price to beat | O4: Supplier name | P4: Supplier type (as shown on listing) | Q4: Listing URL | R4: FOB as listed (US$) | S4: Listed per … (piece / pair / kg / set) | T4: Listed units per sellable unit (e.g. 2 pieces per pair) | U4: FOB per sellable unit (US$) | V4: MOQ (sellable units) | W4: Carton CBM per sellable unit | X4: Carton gross kg per sellable unit | Y4: First-order compliance / testing (A$ one-off per order) | Z4: Per-unit compliance / labels (A$ per unit) | AA4: Per-unit compliance / labels (US$ per unit) | AB4: Per-shipment extras, e.g. biosecurity (A$ per order) | AC4: Duty-free at the general rate? (Yes / No) | AD4: Storage basis (Per CBM / Flat) | AE4: Defect % override (blank = global) | AF4: Factories to inspect | AG4: Shipping mode (LCL / 20GP / 40HQ) | AH4: Order quantity (sellable units) | AI4: FOB (A$ per unit) | AJ4: Units per 20GP (lesser of volume / weight) | AK4: Units per 40HQ (lesser of volume / weight) | AL4: Units per container – selected mode | AM4: Containers needed | AN4: Box fill % (FCL) | AO4: Order CBM | AP4: Order tonnes | AQ4: Freight for the order (A$) | AR4: Freight (A$ per unit) | AS4: Freight if every box were full (A$/unit) = box cost ÷ units that fit | AT4: Duty rate applied | AU4: Duty (A$ per unit) | AV4: Inspection (A$ per unit) | AW4: Compliance (A$ per unit) | AX4: Per-shipment extras (A$ per unit) | AY4: Subtotal before allowances (A$ per unit) | AZ4: Defect % applied | BA4: Defect allowance (A$ per unit) | BB4: Storage / handling (A$ per unit) | BC4: Landed cost (A$ per unit, ex-GST) | BD4: Net revenue (A$ per unit) = price ÷ 1.1 | BE4: GP (A$ per unit) | BF4: GP % | BG4: Total GP for the order (A$) | BH4: Cash required ex-GST (A$) = landed × qty | BI4: Import-GST float (A$, reclaimable) | BJ4: Cash incl. GST float (A$) | BK4: Break-even FOB (US$ per sellable unit) | BL4: Break-even FOB (US$ per listed unit) | BM4: Break-even sale price (A$ incl. GST) | BN4: Fixed costs per order (A$) | BO4: Contribution per unit before fixed costs (A$) | BP4: Units to pay back fixed costs | BQ4: Units to sell to recover the cash outlay | BR4: Freight if LCL (A$) | BS4: Freight if 20GP (A$) | BT4: Freight if 40HQ (A$) | BU4: Cheapest mode at this qty | BV4: Flags | BW4: Why this verdict (verify notes) | BX4: FOB basis and price ladder | BY4: Carton data source | BZ4: Compliance and extras basis | CA4: Other price floors | CB4: Source note
A5: 1 | B5: Kids | C5: Trampoline 14ft + enclosure | D5: 14ft (4.27 m) round spring trampoline with safety enclosure; 150 kg max user; ships as one carton | E5: CONFIRMED | F5: 7 | G5: 7 | H5: 385.95 | I5: Amazon AU – Everfit 14FT trampoline (B08FWVCRG1), '3 offers from' | J5: 9 Oct 2026 (Best Sellers; delivery fee not visible) | K5: 349 | L5: =IF(H5>0,H5*(1-TARGET_DISC),"") -> 347.355 | M5: =IF(AND(PRICE_MODE="Rule",ISNUMBER(L5)),L5,K5) -> 349 | N5: =IF(AND(H5>0,M5>0),1-M5/H5,"") -> 0.09573779 | O5: Zhejiang Lingsha Technology (Funjump), Lishui | P5: Manufacturer & trading | Q5: https://lsfunjump.en.made-in-china.com/product/uphRrGWYIgci/China-Funjump-14FT-Outdoor-Indoor-Fitness-Kid-Child-Mini-Bungee-Jumping-Trampoline-with-Safety-Enclosure.html | R5: 96 | S5: per set (100–499 pcs tier) | T5: 1 | U5: =R5*T5 -> 96 | V5: 100 | W5: 0.2176 | X5: 62 | Y5: 2500 | Z5: 0 | AA5: 0 | AB5: 0 | AC5: No | AD5: Per CBM | AF5: 1 | AG5: 20GP | AH5: 128 | AI5: =U5*USD_TO_AUD -> 138.01035 | AJ5: =IF(W5>0,IF(X5>0,MIN(INT(CBM_20GP/W5+0.000001),INT(KG_20GP/X5+0.000001)),INT(CBM_20GP/W5+0.000001)),0) -> 128 | AK5: =IF(W5>0,IF(X5>0,MIN(INT(CBM_40HQ/W5+0.000001),INT(KG_40HQ/X5+0.000001)),INT(CBM_40HQ/W5+0.000001)),0) -> 312 | AL5: =IF(AG5="20GP",AJ5,IF(AG5="40HQ",AK5,"LCL")) -> 128 | AM5: =IF(AH5<=0,0,IF(AG5="20GP",IF(AJ5>0,ROUNDUP(AH5/AJ5,0),0),IF(AG5="40HQ",IF(AK5>0,ROUNDUP(AH5/AK5,0),0),0))) -> 1 | AN5: =IF(OR(AG5="LCL",AM5=0),"",AH5/(AM5*AL5)) -> 1 | AO5: =AH5*W5 -> 27.8528 | AP5: =AH5*X5/1000 -> 7.936 | AQ5: =IF(AH5<=0,0,IF(AG5="LCL",LCL_RATE*MAX(AO5,AP5)+LCL_FIXED,AM5*IF(AG5="20GP",COST_20GP,COST_40HQ))) -> 5908 | AR5: =IF(AH5>0,AQ5/AH5,0) -> 46.15625 | AS5: =IF(AG5="20GP",IF(AJ5>0,COST_20GP/AJ5,0),IF(AG5="40HQ",IF(AK5>0,COST_40HQ/AK5,0),AR5)) -> 46.15625 | AT5: =IF(AC5="Yes",0,DUTY_APPLIED) -> 0 | AU5: =AI5*AT5 -> 0 | AV5: =IF(AH5>0,INSPECTION*AF5/AH5,0) -> 3.125 | AW5: =IF(AH5>0,Y5/AH5,0)+Z5+AA5*USD_TO_AUD -> 19.53125 | AX5: =IF(AH5>0,(AB5+OTHER_FIXED)/AH5,0) -> 0 | AY5: =AI5+AR5+AU5+AV5+AW5+AX5 -> 206.82285 | AZ5: =IF(ISNUMBER(AE5),AE5,DEFECT_PCT) -> 0.03 | BA5: =AY5*AZ5 -> 6.2046855 | BB5: =IF(AD5="Flat",HANDLING_FLAT,STORAGE_PER_CBM*W5) -> 7.1808 | BC5: =AY5+BA5+BB5 -> 220.20834 | BD5: =M5/(1+GST_RATE)*(1-MP_FEE) -> 317.27273 | BE5: =BD5-BC5 -> 97.064391 | BF5: =IF(BD5<>0,BE5/BD5,0) -> 0.30593361 | BG5: =BE5*AH5 -> 12424.242 | BH5: =BC5*AH5 -> 28186.667 | BI5: =GST_RATE*(AI5+AU5+GST_TI_SHARE*AR5)*AH5 -> 2121.0125 | BJ5: =BH5+BI5 -> 30307.68 | BK5: =((BD5-BB5)/(1+AZ5)-(AR5+AV5+AW5+AX5))/(1+AT5)*FX_AUDUSD -> 161.55145 | BL5: =IF(T5>0,BK5/T5,0) -> 161.55145 | BM5: =BC5*(1+GST_RATE)/(1-MP_FEE) -> 242.22917 | BN5: =IF(AH5<=0,0,INSPECTION*AF5+Y5+AB5+OTHER_FIXED+IF(AG5="LCL",LCL_FIXED,AQ5)) -> 8808 | BO5: =BD5-((AI5+AU5+Z5+AA5*USD_TO_AUD+IF(AND(AG5="LCL",AH5>0),LCL_RATE*MAX(AO5,AP5)/AH5,0))*(1+AZ5)+BB5) -> 167.94127 | BP5: =IF(AH5<=0,"",IF(BO5>0,ROUNDUP(BN5*(1+AZ5)/BO5,0),"Never")) -> 55 | BQ5: =IF(AH5<=0,"",IF(BD5>0,ROUNDUP(BH5/BD5,0),"Never")) -> 89 | BR5: =IF(AH5>0,LCL_RATE*MAX(AO5,AP5)+LCL_FIXED,0) -> 7696.0832 | BS5: =IF(AND(AH5>0,AJ5>0),ROUNDUP(AH5/AJ5,0)*COST_20GP,0) -> 5908 | BT5: =IF(AND(AH5>0,AK5>0),ROUNDUP(AH5/AK5,0)*COST_40HQ,0) -> 10064 | BU5: =IF(AH5<=0,"",IF(BR5<=MIN(BS5,BT5),"LCL",IF(BS5<=BT5,"20GP","40HQ"))) -> 20GP | BV5: =TRIM(IF(AH5<V5,"Below MOQ. ","")&IF(AM5>1,"Needs "&AM5&" containers. ","")&IF(ISNUMBER(AN5),IF(AN5<0.85,"Box only "&TEXT(AN5,"0%")&" full – whole box charged. ",""),"")&IF(AND(BU5<>"",BU5<>AG5),"Cheaper freight at this qty: "&BU5&". ","")&IF(ISNUMBER(N5),IF(N5<0,"Price above price to beat. ",IF(N5<TARGET_DISC-0.0005,"Discount below target. ","")),"")&IF(U5<=0,"FOB missing. ","")&IF(N(X5)=0,"Carton kg missing. ","")&IF(BE5<0,"Loss-making. ","")&IF(ISNUMBER(BQ5),IF(BQ5>AH5,"Cash not recovered even if all units sell. ",""),"")) -> Discount below target. | BW5: Margin holds at 20GP scale: A$349 is 9.6% below Amazon's cheapest 14ft (marginally outside the 10–20% band; A$339 keeps it inside) and is the cheapest per m² of mat. Kmart's 12ft A$299 / 10ft A$199 anchor the low end; Nov–Dec seasonal; needs an AS 4989 / EN 71-14 test plus liability cover. | BX5: Lingsha 14FT ladder US$96 (100–499) / US$93 (500–999) / US$89 (1,000+); FAQ: MOQ 50 per size, a 20GP can mix 3–4 sizes. Alt: Yongkang Nanjian 14FT US$79–129 (MOQ 100, 59 kg); Beijing Set Sail US$119 (probable trader). | BY5: 172×55×23 cm = 0.2176 CBM, 62 kg gross (Lingsha packing table, cited). | BZ5: AS 4989 / EN 71-14 test of the exact build A$2,500 one-off (ESTIMATE – no lab quote). No mandatory standard. HS 9506.91: 5% general, Free with a ChAFTA CoO. | CA5: Toys"R"Us Bestway 14ft A$443.99; Kmart 12ft springless A$299 (snippet); Amazon delivery on big trampolines ~A$120 (OzBargain). | CB5: verify_kids.md Q1
A6: 2 | B6: Kids | C6: Kids 24V 2-seat UTV | D6: 24V 2-seat ride-on UTV with parental remote; lead-acid 24V 7Ah; 4 × 555 motors (Zhehua 110-E1) | E6: BROKEN | F6: 6 | G6: 3 | H6: 339.95 | I6: Amazon AU – HONEY JOY 24V 2-seater ride-on truck with remote (B0HJ1KPG9Q), '1 offer from' | J6: 9 Oct 2026 (carousel price; delivery not visible) | K6: 299 | L6: =IF(H6>0,H6*(1-TARGET_DISC),"") -> 305.955 | M6: =IF(AND(PRICE_MODE="Rule",ISNUMBER(L6)),L6,K6) -> 299 | N6: =IF(AND(H6>0,M6>0),1-M6/H6,"") -> 0.12045889 | O6: Shenzhen Zhehua Technology | P6: Unknown – not stated (office address; probable trader) | Q6: https://zhehuatoys.en.made-in-china.com/product/ZYnrUyqDrdWv/China-24V-Electric-Kids-Car-UTV-2-Seats-Children-Battery-Ride-on-Car.html | R6: 117 | S6: per unit (20–269 tier) | T6: 1 | U6: =R6*T6 -> 117 | V6: 20 | W6: 0.2557 | X6: 31 | Y6: 4129.59 | Z6: 0 | AA6: 0 | AB6: 0 | AC6: Yes | AD6: Per CBM | AF6: 1 | AG6: 20GP | AH6: 98 | AI6: =U6*USD_TO_AUD -> 168.20012 | AJ6: =IF(W6>0,IF(X6>0,MIN(INT(CBM_20GP/W6+0.000001),INT(KG_20GP/X6+0.000001)),INT(CBM_20GP/W6+0.000001)),0) -> 109 | AK6: =IF(W6>0,IF(X6>0,MIN(INT(CBM_40HQ/W6+0.000001),INT(KG_40HQ/X6+0.000001)),INT(CBM_40HQ/W6+0.000001)),0) -> 265 | AL6: =IF(AG6="20GP",AJ6,IF(AG6="40HQ",AK6,"LCL")) -> 109 | AM6: =IF(AH6<=0,0,IF(AG6="20GP",IF(AJ6>0,ROUNDUP(AH6/AJ6,0),0),IF(AG6="40HQ",IF(AK6>0,ROUNDUP(AH6/AK6,0),0),0))) -> 1 | AN6: =IF(OR(AG6="LCL",AM6=0),"",AH6/(AM6*AL6)) -> 0.89908257 | AO6: =AH6*W6 -> 25.0586 | AP6: =AH6*X6/1000 -> 3.038 | AQ6: =IF(AH6<=0,0,IF(AG6="LCL",LCL_RATE*MAX(AO6,AP6)+LCL_FIXED,AM6*IF(AG6="20GP",COST_20GP,COST_40HQ))) -> 5908 | AR6: =IF(AH6>0,AQ6/AH6,0) -> 60.285714 | AS6: =IF(AG6="20GP",IF(AJ6>0,COST_20GP/AJ6,0),IF(AG6="40HQ",IF(AK6>0,COST_40HQ/AK6,0),AR6)) -> 54.201835 | AT6: =IF(AC6="Yes",0,DUTY_APPLIED) -> 0 | AU6: =AI6*AT6 -> 0 | AV6: =IF(AH6>0,INSPECTION*AF6/AH6,0) -> 4.0816327 | AW6: =IF(AH6>0,Y6/AH6,0)+Z6+AA6*USD_TO_AUD -> 42.138673 | AX6: =IF(AH6>0,(AB6+OTHER_FIXED)/AH6,0) -> 0 | AY6: =AI6+AR6+AU6+AV6+AW6+AX6 -> 274.70614 | AZ6: =IF(ISNUMBER(AE6),AE6,DEFECT_PCT) -> 0.03 | BA6: =AY6*AZ6 -> 8.2411841 | BB6: =IF(AD6="Flat",HANDLING_FLAT,STORAGE_PER_CBM*W6) -> 8.4381 | BC6: =AY6+BA6+BB6 -> 291.38542 | BD6: =M6/(1+GST_RATE)*(1-MP_FEE) -> 271.81818 | BE6: =BD6-BC6 -> -19.567238 | BF6: =IF(BD6<>0,BE6/BD6,0) -> -0.071986493 | BG6: =BE6*AH6 -> -1917.5893 | BH6: =BC6*AH6 -> 28555.771 | BI6: =GST_RATE*(AI6+AU6+GST_TI_SHARE*AR6)*AH6 -> 2002.8411 | BJ6: =BH6+BI6 -> 30558.612 | BK6: =((BD6-BB6)/(1+AZ6)-(AR6+AV6+AW6+AX6))/(1+AT6)*FX_AUDUSD -> 103.78547 | BL6: =IF(T6>0,BK6/T6,0) -> 103.78547 | BM6: =BC6*(1+GST_RATE)/(1-MP_FEE) -> 320.52396 | BN6: =IF(AH6<=0,0,INSPECTION*AF6+Y6+AB6+OTHER_FIXED+IF(AG6="LCL",LCL_FIXED,AQ6)) -> 10437.59 | BO6: =BD6-((AI6+AU6+Z6+AA6*USD_TO_AUD+IF(AND(AG6="LCL",AH6>0),LCL_RATE*MAX(AO6,AP6)/AH6,0))*(1+AZ6)+BB6) -> 90.133963 | BP6: =IF(AH6<=0,"",IF(BO6>0,ROUNDUP(BN6*(1+AZ6)/BO6,0),"Never")) -> 120 | BQ6: =IF(AH6<=0,"",IF(BD6>0,ROUNDUP(BH6/BD6,0),"Never")) -> 106 | BR6: =IF(AH6>0,LCL_RATE*MAX(AO6,AP6)+LCL_FIXED,0) -> 7014.2984 | BS6: =IF(AND(AH6>0,AJ6>0),ROUNDUP(AH6/AJ6,0)*COST_20GP,0) -> 5908 | BT6: =IF(AND(AH6>0,AK6>0),ROUNDUP(AH6/AK6,0)*COST_40HQ,0) -> 10064 | BU6: =IF(AH6<=0,"",IF(BR6<=MIN(BS6,BT6),"LCL",IF(BS6<=BT6,"20GP","40HQ"))) -> 20GP | BV6: =TRIM(IF(AH6<V6,"Below MOQ. ","")&IF(AM6>1,"Needs "&AM6&" containers. ","")&IF(ISNUMBER(AN6),IF(AN6<0.85,"Box only "&TEXT(AN6,"0%")&" full – whole box charged. ",""),"")&IF(AND(BU6<>"",BU6<>AG6),"Cheaper freight at this qty: "&BU6&". ","")&IF(ISNUMBER(N6),IF(N6<0,"Price above price to beat. ",IF(N6<TARGET_DISC-0.0005,"Discount below target. ","")),"")&IF(U6<=0,"FOB missing. ","")&IF(N(X6)=0,"Carton kg missing. ","")&IF(BE6<0,"Loss-making. ","")&IF(ISNUMBER(BQ6),IF(BQ6>AH6,"Cash not recovered even if all units sell. ",""),"")) -> Loss-making. Cash not recovered even if all units sell. | BW6: Amazon already sells a 24V 2-seater with remote at A$339.95, so the 10–20% rule caps price at ~A$272–306. At A$299 the first 20GP order loses ~A$20/unit; only a full 40HQ makes ~12%. Genuine Hebei/Jiaxing makers (US$150–178, bigger cartons) lose money at any price up to A$349. | BX6: Zhehua 110-E1 US$117 (20–269) / US$109 (270+). Genuine makers: Hebei Boyi BY-MG2039 US$150 (0.398 CBM), Pinghu United A032 US$178 (0.50 CBM). | BY6: 111×64×36 cm = 0.2557 CBM, 31 kg gross (cited). Supplier states 98 per 20ft / 270 per 40HQ; the volume formula allows 109 per 20GP. | BZ6: A$4,129.59 one-off = toy / electric-toy / EN62115-type testing A$3,000 (EST) + EESS Responsible Supplier A$239.74 + Level 3 charger registration A$89.85 + charger CoC A$800 (EST). HS 9503.00.10 Free at the general rate. Button-battery remote rules; SP 238 SLA battery statement. | CA6: HONEY JOY 24V 2-seat quad A$309.95; HONEY JOY 24V dump truck A$399.95; ANPABO 24V 4WD A$469.99. | CB6: verify_kids.md Q2
A7: 3 | B7: Kids | C7: Timber cubby house | D7: Chinese-fir cubby / cabin with pretend kitchen sink, 107.5×113.5×145.5 cm (Zhongran model 91024) | E7: REVISED | F7: 6 | G7: 5 | H7: 349.97 | I7: Kmart Marketplace – AUSWAY timber cubby 123×106×125 cm (Amazon AU floor not observable) | J7: Undated search snippet (Kmart returned 403) | K7: 299 | L7: =IF(H7>0,H7*(1-TARGET_DISC),"") -> 314.973 | M7: =IF(AND(PRICE_MODE="Rule",ISNUMBER(L7)),L7,K7) -> 299 | N7: =IF(AND(H7>0,M7>0),1-M7/H7,"") -> 0.14564105 | O7: Heze Zhongran Woodware (Shandong) | P7: Manufacturer & trading (self-described) | Q7: https://chinakidstoy.en.made-in-china.com/product/EGLUuvndOCYI/China-Backyard-Garden-Wooden-Kids-Play-Cabin-Children-Outdoor-Playhouse-with-Pretend-Kitchen-Sink-for-Home-Yard-Game.html | R7: 106.12 | S7: per set (MOQ 300 sets) | T7: 1 | U7: =R7*T7 -> 106.12 | V7: 300 | W7: 0.1733 | X7: 31.3 | Y7: 1000 | Z7: 0 | AA7: 0 | AB7: 500 | AC7: No | AD7: Per CBM | AF7: 1 | AG7: 40HQ | AH7: 300 | AI7: =U7*USD_TO_AUD -> 152.55894 | AJ7: =IF(W7>0,IF(X7>0,MIN(INT(CBM_20GP/W7+0.000001),INT(KG_20GP/X7+0.000001)),INT(CBM_20GP/W7+0.000001)),0) -> 161 | AK7: =IF(W7>0,IF(X7>0,MIN(INT(CBM_40HQ/W7+0.000001),INT(KG_40HQ/X7+0.000001)),INT(CBM_40HQ/W7+0.000001)),0) -> 392 | AL7: =IF(AG7="20GP",AJ7,IF(AG7="40HQ",AK7,"LCL")) -> 392 | AM7: =IF(AH7<=0,0,IF(AG7="20GP",IF(AJ7>0,ROUNDUP(AH7/AJ7,0),0),IF(AG7="40HQ",IF(AK7>0,ROUNDUP(AH7/AK7,0),0),0))) -> 1 | AN7: =IF(OR(AG7="LCL",AM7=0),"",AH7/(AM7*AL7)) -> 0.76530612 | AO7: =AH7*W7 -> 51.99 | AP7: =AH7*X7/1000 -> 9.39 | AQ7: =IF(AH7<=0,0,IF(AG7="LCL",LCL_RATE*MAX(AO7,AP7)+LCL_FIXED,AM7*IF(AG7="20GP",COST_20GP,COST_40HQ))) -> 10064 | AR7: =IF(AH7>0,AQ7/AH7,0) -> 33.546667 | AS7: =IF(AG7="20GP",IF(AJ7>0,COST_20GP/AJ7,0),IF(AG7="40HQ",IF(AK7>0,COST_40HQ/AK7,0),AR7)) -> 25.673469 | AT7: =IF(AC7="Yes",0,DUTY_APPLIED) -> 0 | AU7: =AI7*AT7 -> 0 | AV7: =IF(AH7>0,INSPECTION*AF7/AH7,0) -> 1.3333333 | AW7: =IF(AH7>0,Y7/AH7,0)+Z7+AA7*USD_TO_AUD -> 3.3333333 | AX7: =IF(AH7>0,(AB7+OTHER_FIXED)/AH7,0) -> 1.6666667 | AY7: =AI7+AR7+AU7+AV7+AW7+AX7 -> 192.43894 | AZ7: =IF(ISNUMBER(AE7),AE7,DEFECT_PCT) -> 0.03 | BA7: =AY7*AZ7 -> 5.7731683 | BB7: =IF(AD7="Flat",HANDLING_FLAT,STORAGE_PER_CBM*W7) -> 5.7189 | BC7: =AY7+BA7+BB7 -> 203.93101 | BD7: =M7/(1+GST_RATE)*(1-MP_FEE) -> 271.81818 | BE7: =BD7-BC7 -> 67.887172 | BF7: =IF(BD7<>0,BE7/BD7,0) -> 0.24975214 | BG7: =BE7*AH7 -> 20366.151 | BH7: =BC7*AH7 -> 61179.303 | BI7: =GST_RATE*(AI7+AU7+GST_TI_SHARE*AR7)*AH7 -> 5180.6083 | BJ7: =BH7+BI7 -> 66359.911 | BK7: =((BD7-BB7)/(1+AZ7)-(AR7+AV7+AW7+AX7))/(1+AT7)*FX_AUDUSD -> 151.96691 | BL7: =IF(T7>0,BK7/T7,0) -> 151.96691 | BM7: =BC7*(1+GST_RATE)/(1-MP_FEE) -> 224.32411 | BN7: =IF(AH7<=0,0,INSPECTION*AF7+Y7+AB7+OTHER_FIXED+IF(AG7="LCL",LCL_FIXED,AQ7)) -> 11964 | BO7: =BD7-((AI7+AU7+Z7+AA7*USD_TO_AUD+IF(AND(AG7="LCL",AH7>0),LCL_RATE*MAX(AO7,AP7)/AH7,0))*(1+AZ7)+BB7) -> 108.96357 | BP7: =IF(AH7<=0,"",IF(BO7>0,ROUNDUP(BN7*(1+AZ7)/BO7,0),"Never")) -> 114 | BQ7: =IF(AH7<=0,"",IF(BD7>0,ROUNDUP(BH7/BD7,0),"Never")) -> 226 | BR7: =IF(AH7>0,LCL_RATE*MAX(AO7,AP7)+LCL_FIXED,0) -> 13585.56 | BS7: =IF(AND(AH7>0,AJ7>0),ROUNDUP(AH7/AJ7,0)*COST_20GP,0) -> 11816 | BT7: =IF(AND(AH7>0,AK7>0),ROUNDUP(AH7/AK7,0)*COST_40HQ,0) -> 10064 | BU7: =IF(AH7<=0,"",IF(BR7<=MIN(BS7,BT7),"LCL",IF(BS7<=BT7,"20GP","40HQ"))) -> 40HQ | BV7: =TRIM(IF(AH7<V7,"Below MOQ. ","")&IF(AM7>1,"Needs "&AM7&" containers. ","")&IF(ISNUMBER(AN7),IF(AN7<0.85,"Box only "&TEXT(AN7,"0%")&" full – whole box charged. ",""),"")&IF(AND(BU7<>"",BU7<>AG7),"Cheaper freight at this qty: "&BU7&". ","")&IF(ISNUMBER(N7),IF(N7<0,"Price above price to beat. ",IF(N7<TARGET_DISC-0.0005,"Discount below target. ","")),"")&IF(U7<=0,"FOB missing. ","")&IF(N(X7)=0,"Carton kg missing. ","")&IF(BE7<0,"Loss-making. ","")&IF(ISNUMBER(BQ7),IF(BQ7>AH7,"Cash not recovered even if all units sell. ",""),"")) -> Box only 77% full – whole box charged. | BW7: A$299 is ~15% under Kmart Marketplace's A$349.97–399 timber cubbies, but Kmart's own Activo cubby has a A$169 RRP (seen at A$99 clearance). Zhongran's MOQ 300 forces a ~40HQ first order (~A$61k cash); needs a timber treatment certificate and storage declaration. | BX7: Zhongran 91024 US$106.12, MOQ 300 (its other playhouses US$87–325). Alt: Ningbo Dreamgo playhouse US$103.88 (50–499) / US$86.57 (500+), 0.134 CBM, 24 kg → 200 units in a 20GP: GP A$73.36 (27.0%) per the notes. | BY7: 103×51×33 cm = 0.1733 CBM, 31.3 kg gross (cited). | BZ7: Optional EN71-3 coating + sharp-edge check A$1,000 one-off (EST). Biosecurity A$500 per shipment (EST): offshore heat/fumigation certificate, storage declaration, inspection contingency. 5% general / Free with CoO. | CA7: Kmart Marketplace Rovo A$399; Kmart own Activo cubby RRP A$169; Bunnings Sweetwater cedar A$549; Lifespan cubbies A$629.99+. | CB7: verify_kids.md Q3
A8: 4 | B8: Kids | C8: 3-in-1 high chair | D8: 3-in-1 convertible high chair (plastic): high chair / booster / toddler chair | E8: BROKEN | F8: 5 | G8: 2 | H8: 89.95 | I8: Amazon AU – BABY JOY 5-in-1 convertible highchair (B0H8CNJ56Q); cheapest convertible A$55.95 | J8: 9 Oct 2026 (Best Sellers; delivery not visible) | K8: 79 | L8: =IF(H8>0,H8*(1-TARGET_DISC),"") -> 80.955 | M8: =IF(AND(PRICE_MODE="Rule",ISNUMBER(L8)),L8,K8) -> 79 | N8: =IF(AND(H8>0,M8>0),1-M8/H8,"") -> 0.1217343 | O8: Hebei Biwei Import & Export Trade | P8: Trading company | Q8: https://hebeibiwei.en.made-in-china.com/product/zUdYeEiPEZcF/China-3-in-1-Baby-Dining-Chair-Multi-Functional-Portable-Baby-High-Chair-Adjustable-Baby-Infant-Dining-Seat-Eating-Feeding-Chair.html | R8: 33.8 | S8: per unit (50–499 tier) | T8: 1 | U8: =R8*T8 -> 33.8 | V8: 50 | W8: 0.0906 | Y8: 2000 | Z8: 0 | AA8: 0 | AB8: 0 | AC8: No | AD8: Flat | AF8: 1 | AG8: LCL | AH8: 150 | AI8: =U8*USD_TO_AUD -> 48.591144 | AJ8: =IF(W8>0,IF(X8>0,MIN(INT(CBM_20GP/W8+0.000001),INT(KG_20GP/X8+0.000001)),INT(CBM_20GP/W8+0.000001)),0) -> 309 | AK8: =IF(W8>0,IF(X8>0,MIN(INT(CBM_40HQ/W8+0.000001),INT(KG_40HQ/X8+0.000001)),INT(CBM_40HQ/W8+0.000001)),0) -> 750 | AL8: =IF(AG8="20GP",AJ8,IF(AG8="40HQ",AK8,"LCL")) -> LCL | AM8: =IF(AH8<=0,0,IF(AG8="20GP",IF(AJ8>0,ROUNDUP(AH8/AJ8,0),0),IF(AG8="40HQ",IF(AK8>0,ROUNDUP(AH8/AK8,0),0),0))) -> 0 | AN8: =IF(OR(AG8="LCL",AM8=0),"",AH8/(AM8*AL8)) | AO8: =AH8*W8 -> 13.59 | AP8: =AH8*X8/1000 -> 0 | AQ8: =IF(AH8<=0,0,IF(AG8="LCL",LCL_RATE*MAX(AO8,AP8)+LCL_FIXED,AM8*IF(AG8="20GP",COST_20GP,COST_40HQ))) -> 4215.96 | AR8: =IF(AH8>0,AQ8/AH8,0) -> 28.1064 | AS8: =IF(AG8="20GP",IF(AJ8>0,COST_20GP/AJ8,0),IF(AG8="40HQ",IF(AK8>0,COST_40HQ/AK8,0),AR8)) -> 28.1064 | AT8: =IF(AC8="Yes",0,DUTY_APPLIED) -> 0 | AU8: =AI8*AT8 -> 0 | AV8: =IF(AH8>0,INSPECTION*AF8/AH8,0) -> 2.6666667 | AW8: =IF(AH8>0,Y8/AH8,0)+Z8+AA8*USD_TO_AUD -> 13.333333 | AX8: =IF(AH8>0,(AB8+OTHER_FIXED)/AH8,0) -> 0 | AY8: =AI8+AR8+AU8+AV8+AW8+AX8 -> 92.697544 | AZ8: =IF(ISNUMBER(AE8),AE8,DEFECT_PCT) -> 0.03 | BA8: =AY8*AZ8 -> 2.7809263 | BB8: =IF(AD8="Flat",HANDLING_FLAT,STORAGE_PER_CBM*W8) -> 5 | BC8: =AY8+BA8+BB8 -> 100.47847 | BD8: =M8/(1+GST_RATE)*(1-MP_FEE) -> 71.818182 | BE8: =BD8-BC8 -> -28.660289 | BF8: =IF(BD8<>0,BE8/BD8,0) -> -0.39906731 | BG8: =BE8*AH8 -> -4299.0433 | BH8: =BC8*AH8 -> 15071.771 | BI8: =GST_RATE*(AI8+AU8+GST_TI_SHARE*AR8)*AH8 -> 981.82477 | BJ8: =BH8+BI8 -> 16053.595 | BK8: =((BD8-BB8)/(1+AZ8)-(AR8+AV8+AW8+AX8))/(1+AT8)*FX_AUDUSD -> 14.444566 | BL8: =IF(T8>0,BK8/T8,0) -> 14.444566 | BM8: =BC8*(1+GST_RATE)/(1-MP_FEE) -> 110.52632 | BN8: =IF(AH8<=0,0,INSPECTION*AF8+Y8+AB8+OTHER_FIXED+IF(AG8="LCL",LCL_FIXED,AQ8)) -> 3300 | BO8: =BD8-((AI8+AU8+Z8+AA8*USD_TO_AUD+IF(AND(AG8="LCL",AH8>0),LCL_RATE*MAX(AO8,AP8)/AH8,0))*(1+AZ8)+BB8) -> -6.0002888 | BP8: =IF(AH8<=0,"",IF(BO8>0,ROUNDUP(BN8*(1+AZ8)/BO8,0),"Never")) -> Never | BQ8: =IF(AH8<=0,"",IF(BD8>0,ROUNDUP(BH8/BD8,0),"Never")) -> 210 | BR8: =IF(AH8>0,LCL_RATE*MAX(AO8,AP8)+LCL_FIXED,0) -> 4215.96 | BS8: =IF(AND(AH8>0,AJ8>0),ROUNDUP(AH8/AJ8,0)*COST_20GP,0) -> 5908 | BT8: =IF(AND(AH8>0,AK8>0),ROUNDUP(AH8/AK8,0)*COST_40HQ,0) -> 10064 | BU8: =IF(AH8<=0,"",IF(BR8<=MIN(BS8,BT8),"LCL",IF(BS8<=BT8,"20GP","40HQ"))) -> LCL | BV8: =TRIM(IF(AH8<V8,"Below MOQ. ","")&IF(AM8>1,"Needs "&AM8&" containers. ","")&IF(ISNUMBER(AN8),IF(AN8<0.85,"Box only "&TEXT(AN8,"0%")&" full – whole box charged. ",""),"")&IF(AND(BU8<>"",BU8<>AG8),"Cheaper freight at this qty: "&BU8&". ","")&IF(ISNUMBER(N8),IF(N8<0,"Price above price to beat. ",IF(N8<TARGET_DISC-0.0005,"Discount below target. ","")),"")&IF(U8<=0,"FOB missing. ","")&IF(N(X8)=0,"Carton kg missing. ","")&IF(BE8<0,"Loss-making. ","")&IF(ISNUMBER(BQ8),IF(BQ8>AH8,"Cash not recovered even if all units sell. ",""),"")) -> Carton kg missing. Loss-making. Cash not recovered even if all units sell. | BW8: Amazon has a dense floor of convertible chairs at A$55.95–89.95 and Kmart Group's Anko sells A$45–149, so the rule price is ~A$79. Landed cost is A$70–100/unit, so a first order loses ~A$29/unit and even a full 40HQ only breaks even. | BX8: Biwei US$33.80 (50–499) / US$32.80 (500–1,199) / US$31.30 (1,200–4,999) / US$30.00 (5,000+). Alt: Ningbo Jiangbei Ringlong US$38.99–40.00, MOQ 500. | BY8: Biwei carton not captured: CBM assumed = Ringlong carton 64×29.5×48 cm (0.0906 CBM), as in the verify note. Carton kg MISSING – left blank (Ringlong's carton is 8 kg). | BZ8: Voluntary AS 4684 / EN 14988 test A$2,000 one-off (EST). Flat A$5 handling (compact item). Infant Products Information Standard warnings apply if the seat reclines or is marketed under 12 months. 5% general. | CA8: BABY JOY 4-in-1 A$55.95; generic 3-in-1 A$79.99; BABY JOY 3-in-1 wooden A$82.95; Target Anko A$45–149. | CB8: verify_kids.md Q4
A9: 5 | B9: Furniture | C9: Dual-motor standing desk | D9: Dual-motor electric sit-stand desk: 3-stage frame (120 kg) + ~140×70 cm top | E9: REVISED | F9: 7 | G9: 6 | H9: 319.9 | I9: Advwin (brand-direct) dual-motor 140×60 desk; Amazon AU cheapest complete dual-motor A$439.99 (FLEXISPOT E3) | J9: 9 Oct 2026 (+ postcode-based delivery) | K9: 299 | L9: =IF(H9>0,H9*(1-TARGET_DISC),"") -> 287.91 | M9: =IF(AND(PRICE_MODE="Rule",ISNUMBER(L9)),L9,K9) -> 299 | N9: =IF(AND(H9>0,M9>0),1-M9/H9,"") -> 0.065332917 | O9: Zhejiang Prorials Advanced Materials (frame) | P9: Manufacturer & trading | Q9: https://chinapurui.en.made-in-china.com/product/JRbUSIKobqVf/China-Fast-Lift-Dual-Motor-Electric-Height-Adjustable-Standing-Office-Desk-Frame.html | R9: 100 | S9: per complete desk (frame US$76 listed + top US$24 est.) | T9: 1 | U9: =R9*T9 -> 100 | V9: 100 | W9: 0.102 | X9: 38.5 | Y9: 3329.59 | Z9: 0 | AA9: 0 | AB9: 0 | AC9: No | AD9: Per CBM | AF9: 1 | AG9: LCL | AH9: 100 | AI9: =U9*USD_TO_AUD -> 143.76078 | AJ9: =IF(W9>0,IF(X9>0,MIN(INT(CBM_20GP/W9+0.000001),INT(KG_20GP/X9+0.000001)),INT(CBM_20GP/W9+0.000001)),0) -> 274 | AK9: =IF(W9>0,IF(X9>0,MIN(INT(CBM_40HQ/W9+0.000001),INT(KG_40HQ/X9+0.000001)),INT(CBM_40HQ/W9+0.000001)),0) -> 571 | AL9: =IF(AG9="20GP",AJ9,IF(AG9="40HQ",AK9,"LCL")) -> LCL | AM9: =IF(AH9<=0,0,IF(AG9="20GP",IF(AJ9>0,ROUNDUP(AH9/AJ9,0),0),IF(AG9="40HQ",IF(AK9>0,ROUNDUP(AH9/AK9,0),0),0))) -> 0 | AN9: =IF(OR(AG9="LCL",AM9=0),"",AH9/(AM9*AL9)) | AO9: =AH9*W9 -> 10.2 | AP9: =AH9*X9/1000 -> 3.85 | AQ9: =IF(AH9<=0,0,IF(AG9="LCL",LCL_RATE*MAX(AO9,AP9)+LCL_FIXED,AM9*IF(AG9="20GP",COST_20GP,COST_40HQ))) -> 3388.8 | AR9: =IF(AH9>0,AQ9/AH9,0) -> 33.888 | AS9: =IF(AG9="20GP",IF(AJ9>0,COST_20GP/AJ9,0),IF(AG9="40HQ",IF(AK9>0,COST_40HQ/AK9,0),AR9)) -> 33.888 | AT9: =IF(AC9="Yes",0,DUTY_APPLIED) -> 0 | AU9: =AI9*AT9 -> 0 | AV9: =IF(AH9>0,INSPECTION*AF9/AH9,0) -> 4 | AW9: =IF(AH9>0,Y9/AH9,0)+Z9+AA9*USD_TO_AUD -> 33.2959 | AX9: =IF(AH9>0,(AB9+OTHER_FIXED)/AH9,0) -> 0 | AY9: =AI9+AR9+AU9+AV9+AW9+AX9 -> 214.94468 | AZ9: =IF(ISNUMBER(AE9),AE9,DEFECT_PCT) -> 0.03 | BA9: =AY9*AZ9 -> 6.4483405 | BB9: =IF(AD9="Flat",HANDLING_FLAT,STORAGE_PER_CBM*W9) -> 3.366 | BC9: =AY9+BA9+BB9 -> 224.75902 | BD9: =M9/(1+GST_RATE)*(1-MP_FEE) -> 271.81818 | BE9: =BD9-BC9 -> 47.059159 | BF9: =IF(BD9<>0,BE9/BD9,0) -> 0.17312734 | BG9: =BE9*AH9 -> 4705.9159 | BH9: =BC9*AH9 -> 22475.902 | BI9: =GST_RATE*(AI9+AU9+GST_TI_SHARE*AR9)*AH9 -> 1640.9358 | BJ9: =BH9+BI9 -> 24116.838 | BK9: =((BD9-BB9)/(1+AZ9)-(AR9+AV9+AW9+AX9))/(1+AT9)*FX_AUDUSD -> 131.78092 | BL9: =IF(T9>0,BK9/T9,0) -> 131.78092 | BM9: =BC9*(1+GST_RATE)/(1-MP_FEE) -> 247.23492 | BN9: =IF(AH9<=0,0,INSPECTION*AF9+Y9+AB9+OTHER_FIXED+IF(AG9="LCL",LCL_FIXED,AQ9)) -> 4629.59 | BO9: =BD9-((AI9+AU9+Z9+AA9*USD_TO_AUD+IF(AND(AG9="LCL",AH9>0),LCL_RATE*MAX(AO9,AP9)/AH9,0))*(1+AZ9)+BB9) -> 94.743936 | BP9: =IF(AH9<=0,"",IF(BO9>0,ROUNDUP(BN9*(1+AZ9)/BO9,0),"Never")) -> 51 | BQ9: =IF(AH9<=0,"",IF(BD9>0,ROUNDUP(BH9/BD9,0),"Never")) -> 83 | BR9: =IF(AH9>0,LCL_RATE*MAX(AO9,AP9)+LCL_FIXED,0) -> 3388.8 | BS9: =IF(AND(AH9>0,AJ9>0),ROUNDUP(AH9/AJ9,0)*COST_20GP,0) -> 5908 | BT9: =IF(AND(AH9>0,AK9>0),ROUNDUP(AH9/AK9,0)*COST_40HQ,0) -> 10064 | BU9: =IF(AH9<=0,"",IF(BR9<=MIN(BS9,BT9),"LCL",IF(BS9<=BT9,"20GP","40HQ"))) -> LCL | BV9: =TRIM(IF(AH9<V9,"Below MOQ. ","")&IF(AM9>1,"Needs "&AM9&" containers. ","")&IF(ISNUMBER(AN9),IF(AN9<0.85,"Box only "&TEXT(AN9,"0%")&" full – whole box charged. ",""),"")&IF(AND(BU9<>"",BU9<>AG9),"Cheaper freight at this qty: "&BU9&". ","")&IF(ISNUMBER(N9),IF(N9<0,"Price above price to beat. ",IF(N9<TARGET_DISC-0.0005,"Discount below target. ","")),"")&IF(U9<=0,"FOB missing. ","")&IF(N(X9)=0,"Carton kg missing. ","")&IF(BE9<0,"Loss-making. ","")&IF(ISNUMBER(BQ9),IF(BQ9>AH9,"Cash not recovered even if all units sell. ",""),"")) -> Discount below target. | BW9: A$299 is 32% under Amazon's cheapest complete dual-motor desk but only 6.5% under Advwin's A$319.90, so it is a ceiling. ~A$47/unit on a 100-desk LCL first order; A$84 on a full 20GP (274) and A$95 on a 40HQ (571). The EESS test cost is unverified. | BX9: US$100 = Prorials dual-motor frame US$76 (100–499; US$75 500–999; US$74 1,000+) + US$24 for a 140×70 particleboard top (ESTIMATE – no top FOB found). Cross-check: Lumi Legend complete dual-motor desk US$99–129 (MOQ 100). | BY9: 0.102 CBM = frame carton 0.057 (cited, 0.97×0.395×0.15 m) + top 0.045 (EST); 38.5 kg = 25 kg (cited) + 13.5 kg (EST). | BZ9: A$3,329.59 one-off = A$3,000 test/certification (EST) + EESS Responsible Supplier A$239.74 + equipment registration A$89.85. Prefer an integrated control box with IEC/CB reports. HS 9403.10 5% general. | CA9: Dual-motor frames from A$199.99 (Amazon); single-motor 140×70 desks A$199.95–259.99 delivered; FF/IKEA/Desky A$579–765. | CB9: verify_furniture.md Q1
A10: 6 | B10: Furniture | C10: Manual fabric recliner | D10: Full-size manual fabric recliner with footrest (Baoyi 'Dark Grey Fabric Manual Relax Recliner') | E10: BROKEN | F10: 6 | G10: 2 | H10: 160.95 | I10: Amazon AU – Artiss A4 fabric recliner with footrest (B07WRTRGB9), New (3) from | J10: 9 Oct 2026 (FREE delivery) | K10: 139 | L10: =IF(H10>0,H10*(1-TARGET_DISC),"") -> 144.855 | M10: =IF(AND(PRICE_MODE="Rule",ISNUMBER(L10)),L10,K10) -> 139 | N10: =IF(AND(H10>0,M10>0),1-M10/H10,"") -> 0.13637776 | O10: Anji Baoyi Information Technology | P10: Unknown – no manufacturer badge (Anhui origin; probable trader) | Q10: https://anjibaoyi.en.made-in-china.com/product/fLupXEDTmmkH/China-Home-Furniture-Dark-Grey-Fabric-Manual-Relax-Recliner.html | R10: 85 | S10: per unit (ladder US$63–93) | T10: 1 | U10: =R10*T10 -> 85 | V10: 30 | W10: 0.333 | X10: 33 | Y10: 300 | Z10: 0.3 | AA10: 0 | AB10: 300 | AC10: No | AD10: Per CBM | AF10: 1 | AG10: 20GP | AH10: 84 | AI10: =U10*USD_TO_AUD -> 122.19666 | AJ10: =IF(W10>0,IF(X10>0,MIN(INT(CBM_20GP/W10+0.000001),INT(KG_20GP/X10+0.000001)),INT(CBM_20GP/W10+0.000001)),0) -> 84 | AK10: =IF(W10>0,IF(X10>0,MIN(INT(CBM_40HQ/W10+0.000001),INT(KG_40HQ/X10+0.000001)),INT(CBM_40HQ/W10+0.000001)),0) -> 204 | AL10: =IF(AG10="20GP",AJ10,IF(AG10="40HQ",AK10,"LCL")) -> 84 | AM10: =IF(AH10<=0,0,IF(AG10="20GP",IF(AJ10>0,ROUNDUP(AH10/AJ10,0),0),IF(AG10="40HQ",IF(AK10>0,ROUNDUP(AH10/AK10,0),0),0))) -> 1 | AN10: =IF(OR(AG10="LCL",AM10=0),"",AH10/(AM10*AL10)) -> 1 | AO10: =AH10*W10 -> 27.972 | AP10: =AH10*X10/1000 -> 2.772 | AQ10: =IF(AH10<=0,0,IF(AG10="LCL",LCL_RATE*MAX(AO10,AP10)+LCL_FIXED,AM10*IF(AG10="20GP",COST_20GP,COST_40HQ))) -> 5908 | AR10: =IF(AH10>0,AQ10/AH10,0) -> 70.333333 | AS10: =IF(AG10="20GP",IF(AJ10>0,COST_20GP/AJ10,0),IF(AG10="40HQ",IF(AK10>0,COST_40HQ/AK10,0),AR10)) -> 70.333333 | AT10: =IF(AC10="Yes",0,DUTY_APPLIED) -> 0 | AU10: =AI10*AT10 -> 0 | AV10: =IF(AH10>0,INSPECTION*AF10/AH10,0) -> 4.7619048 | AW10: =IF(AH10>0,Y10/AH10,0)+Z10+AA10*USD_TO_AUD -> 3.8714286 | AX10: =IF(AH10>0,(AB10+OTHER_FIXED)/AH10,0) -> 3.5714286 | AY10: =AI10+AR10+AU10+AV10+AW10+AX10 -> 204.73476 | AZ10: =IF(ISNUMBER(AE10),AE10,DEFECT_PCT) -> 0.03 | BA10: =AY10*AZ10 -> 6.1420428 | BB10: =IF(AD10="Flat",HANDLING_FLAT,STORAGE_PER_CBM*W10) -> 10.989 | BC10: =AY10+BA10+BB10 -> 221.8658 | BD10: =M10/(1+GST_RATE)*(1-MP_FEE) -> 126.36364 | BE10: =BD10-BC10 -> -95.502166 | BF10: =IF(BD10<>0,BE10/BD10,0) -> -0.75577254 | BG10: =BE10*AH10 -> -8022.182 | BH10: =BC10*AH10 -> 18636.727 | BI10: =GST_RATE*(AI10+AU10+GST_TI_SHARE*AR10)*AH10 -> 1380.932 | BJ10: =BH10+BI10 -> 20017.659 | BK10: =((BD10-BB10)/(1+AZ10)-(AR10+AV10+AW10+AX10))/(1+AT10)*FX_AUDUSD -> 20.503585 | BL10: =IF(T10>0,BK10/T10,0) -> 20.503585 | BM10: =BC10*(1+GST_RATE)/(1-MP_FEE) -> 244.05238 | BN10: =IF(AH10<=0,0,INSPECTION*AF10+Y10+AB10+OTHER_FIXED+IF(AG10="LCL",LCL_FIXED,AQ10)) -> 6908 | BO10: =BD10-((AI10+AU10+Z10+AA10*USD_TO_AUD+IF(AND(AG10="LCL",AH10>0),LCL_RATE*MAX(AO10,AP10)/AH10,0))*(1+AZ10)+BB10) -> -10.796928 | BP10: =IF(AH10<=0,"",IF(BO10>0,ROUNDUP(BN10*(1+AZ10)/BO10,0),"Never")) -> Never | BQ10: =IF(AH10<=0,"",IF(BD10>0,ROUNDUP(BH10/BD10,0),"Never")) -> 148 | BR10: =IF(AH10>0,LCL_RATE*MAX(AO10,AP10)+LCL_FIXED,0) -> 7725.168 | BS10: =IF(AND(AH10>0,AJ10>0),ROUNDUP(AH10/AJ10,0)*COST_20GP,0) -> 5908 | BT10: =IF(AND(AH10>0,AK10>0),ROUNDUP(AH10/AK10,0)*COST_40HQ,0) -> 10064 | BU10: =IF(AH10<=0,"",IF(BR10<=MIN(BS10,BT10),"LCL",IF(BS10<=BT10,"20GP","40HQ"))) -> 20GP | BV10: =TRIM(IF(AH10<V10,"Below MOQ. ","")&IF(AM10>1,"Needs "&AM10&" containers. ","")&IF(ISNUMBER(AN10),IF(AN10<0.85,"Box only "&TEXT(AN10,"0%")&" full – whole box charged. ",""),"")&IF(AND(BU10<>"",BU10<>AG10),"Cheaper freight at this qty: "&BU10&". ","")&IF(ISNUMBER(N10),IF(N10<0,"Price above price to beat. ",IF(N10<TARGET_DISC-0.0005,"Discount below target. ","")),"")&IF(U10<=0,"FOB missing. ","")&IF(N(X10)=0,"Carton kg missing. ","")&IF(BE10<0,"Loss-making. ","")&IF(ISNUMBER(BQ10),IF(BQ10>AH10,"Cash not recovered even if all units sell. ",""),"")) -> Loss-making. Cash not recovered even if all units sell. | BW10: The original comparator was a swivel-rocker; a like-for-like Artiss A4 sells from A$160.95 delivered. At a rule-compliant A$139, landed cost of A$193–222 gives −A$67 to −A$96 per unit; the 0.33 CBM cube kills it. | BX10: Baoyi ladder US$63–93 (MOQ 30); verify base US$85. Rocker-swivel alt: Anji Jikeyuan 9151-1 US$85–125 (0.511 CBM, 50 kg). | BY10: 0.333 CBM inferred from the listing's '204 pieces/40HQ'; 33 kg ESTIMATE (no carton data listed). | BZ10: A$300 one-off + A$0.30/unit care label (EST); biosecurity contingency A$300 per shipment (EST; ICS untreated-wood question for 9401.61). 5% general. | CA10: Artiss A1 push-back A$159.95 + A$44.72 delivery; La Bella Shiloh A$229; original comparator Artiss A15 swivel-rocker A$389.95. | CB10: verify_furniture.md Q2
A11: 7 | B11: Furniture | C11: Fluted/LED TV unit 160cm | D11: Premium fluted / LED TV entertainment unit 160–190 cm; USB 5 V LED with IR remote (no mains adapter or AC outlets) | E11: BROKEN (as specified) | F11: 6 | G11: 3 | H11: 149.95 | I11: Amazon AU – Artiss 160 cm fluted TV unit (B0GJRDBT14) | J11: 9 Oct 2026 (FREE delivery; '−53%' promo price) | K11: 129 | L11: =IF(H11>0,H11*(1-TARGET_DISC),"") -> 134.955 | M11: =IF(AND(PRICE_MODE="Rule",ISNUMBER(L11)),L11,K11) -> 129 | N11: =IF(AND(H11>0,M11>0),1-M11/H11,"") -> 0.13971324 | O11: Shandong Sail Furniture | P11: Manufacturer & trading | Q11: https://sail-furniture.en.made-in-china.com/product/vaWUPEyJqLrk/China-Living-Room-Bedroom-Hotel-Modern-Contemporary-LED-Light-TV-Stands.html | R11: 45 | S11: per unit (verify base) | T11: 1 | U11: =R11*T11 -> 45 | V11: 100 | W11: 0.15 | X11: 38 | Y11: 800 | Z11: 1.5 | AA11: 0 | AB11: 0 | AC11: No | AD11: Per CBM | AF11: 1 | AG11: LCL | AH11: 100 | AI11: =U11*USD_TO_AUD -> 64.692352 | AJ11: =IF(W11>0,IF(X11>0,MIN(INT(CBM_20GP/W11+0.000001),INT(KG_20GP/X11+0.000001)),INT(CBM_20GP/W11+0.000001)),0) -> 186 | AK11: =IF(W11>0,IF(X11>0,MIN(INT(CBM_40HQ/W11+0.000001),INT(KG_40HQ/X11+0.000001)),INT(CBM_40HQ/W11+0.000001)),0) -> 453 | AL11: =IF(AG11="20GP",AJ11,IF(AG11="40HQ",AK11,"LCL")) -> LCL | AM11: =IF(AH11<=0,0,IF(AG11="20GP",IF(AJ11>0,ROUNDUP(AH11/AJ11,0),0),IF(AG11="40HQ",IF(AK11>0,ROUNDUP(AH11/AK11,0),0),0))) -> 0 | AN11: =IF(OR(AG11="LCL",AM11=0),"",AH11/(AM11*AL11)) | AO11: =AH11*W11 -> 15 | AP11: =AH11*X11/1000 -> 3.8 | AQ11: =IF(AH11<=0,0,IF(AG11="LCL",LCL_RATE*MAX(AO11,AP11)+LCL_FIXED,AM11*IF(AG11="20GP",COST_20GP,COST_40HQ))) -> 4560 | AR11: =IF(AH11>0,AQ11/AH11,0) -> 45.6 | AS11: =IF(AG11="20GP",IF(AJ11>0,COST_20GP/AJ11,0),IF(AG11="40HQ",IF(AK11>0,COST_40HQ/AK11,0),AR11)) -> 45.6 | AT11: =IF(AC11="Yes",0,DUTY_APPLIED) -> 0 | AU11: =AI11*AT11 -> 0 | AV11: =IF(AH11>0,INSPECTION*AF11/AH11,0) -> 4 | AW11: =IF(AH11>0,Y11/AH11,0)+Z11+AA11*USD_TO_AUD -> 9.5 | AX11: =IF(AH11>0,(AB11+OTHER_FIXED)/AH11,0) -> 0 | AY11: =AI11+AR11+AU11+AV11+AW11+AX11 -> 123.79235 | AZ11: =IF(ISNUMBER(AE11),AE11,DEFECT_PCT) -> 0.03 | BA11: =AY11*AZ11 -> 3.7137706 | BB11: =IF(AD11="Flat",HANDLING_FLAT,STORAGE_PER_CBM*W11) -> 4.95 | BC11: =AY11+BA11+BB11 -> 132.45612 | BD11: =M11/(1+GST_RATE)*(1-MP_FEE) -> 117.27273 | BE11: =BD11-BC11 -> -15.183395 | BF11: =IF(BD11<>0,BE11/BD11,0) -> -0.12947081 | BG11: =BE11*AH11 -> -1518.3395 | BH11: =BC11*AH11 -> 13245.612 | BI11: =GST_RATE*(AI11+AU11+GST_TI_SHARE*AR11)*AH11 -> 920.52352 | BJ11: =BH11+BI11 -> 14166.136 | BK11: =((BD11-BB11)/(1+AZ11)-(AR11+AV11+AW11+AX11))/(1+AT11)*FX_AUDUSD -> 34.746049 | BL11: =IF(T11>0,BK11/T11,0) -> 34.746049 | BM11: =BC11*(1+GST_RATE)/(1-MP_FEE) -> 145.70173 | BN11: =IF(AH11<=0,0,INSPECTION*AF11+Y11+AB11+OTHER_FIXED+IF(AG11="LCL",LCL_FIXED,AQ11)) -> 2100 | BO11: =BD11-((AI11+AU11+Z11+AA11*USD_TO_AUD+IF(AND(AG11="LCL",AH11>0),LCL_RATE*MAX(AO11,AP11)/AH11,0))*(1+AZ11)+BB11) -> 6.4466048 | BP11: =IF(AH11<=0,"",IF(BO11>0,ROUNDUP(BN11*(1+AZ11)/BO11,0),"Never")) -> 336 | BQ11: =IF(AH11<=0,"",IF(BD11>0,ROUNDUP(BH11/BD11,0),"Never")) -> 113 | BR11: =IF(AH11>0,LCL_RATE*MAX(AO11,AP11)+LCL_FIXED,0) -> 4560 | BS11: =IF(AND(AH11>0,AJ11>0),ROUNDUP(AH11/AJ11,0)*COST_20GP,0) -> 5908 | BT11: =IF(AND(AH11>0,AK11>0),ROUNDUP(AH11/AK11,0)*COST_40HQ,0) -> 10064 | BU11: =IF(AH11<=0,"",IF(BR11<=MIN(BS11,BT11),"LCL",IF(BS11<=BT11,"20GP","40HQ"))) -> LCL | BV11: =TRIM(IF(AH11<V11,"Below MOQ. ","")&IF(AM11>1,"Needs "&AM11&" containers. ","")&IF(ISNUMBER(AN11),IF(AN11<0.85,"Box only "&TEXT(AN11,"0%")&" full – whole box charged. ",""),"")&IF(AND(BU11<>"",BU11<>AG11),"Cheaper freight at this qty: "&BU11&". ","")&IF(ISNUMBER(N11),IF(N11<0,"Price above price to beat. ",IF(N11<TARGET_DISC-0.0005,"Discount below target. ","")),"")&IF(U11<=0,"FOB missing. ","")&IF(N(X11)=0,"Carton kg missing. ","")&IF(BE11<0,"Loss-making. ","")&IF(ISNUMBER(BQ11),IF(BQ11>AH11,"Cash not recovered even if all units sell. ",""),"")) -> Loss-making. Cash not recovered even if all units sell. | BW11: Fluted and LED looks are commodity on Amazon AU: Artiss 160 cm fluted is A$149.95 free-delivered and LED units start at A$117.80. At a rule-compliant A$129: −A$15 (LCL-100), +A$5 (20GP), +A$18 (40HQ). Toppling-furniture warnings apply to the listing itself. | BX11: US$45 = verify base between Sail / Feilu LED units (US$38–42, MOQ 100) and Jianmu Shijia fluted (US$43.80–49.80). Sail ladder US$42 (100–499) / US$40 / US$38 (1,000+). | BY11: 0.15 CBM / 38 kg ESTIMATES (no verified carton for a 160–190 cm unit; Sail's 160×50×75 cm package field is implausible). | BZ11: A$800 one-off = label artwork A$300 + EMC report review A$500 (EST) + A$1.50/unit for permanent toppling label, anchor kit and insert (EST). Toppling Furniture Information Standard 2024 (warning must appear in the Marketplace listing). 5% general. | CA11: Ufurniture 160 cm LED A$82.90 + A$34.90 delivery = A$117.80; ALFORDSON 180 cm fluted A$169.95; Advwin 160 cm RGB LED A$129.90 direct. | CB11: verify_furniture.md Q3
